<?xml version="1.0"?>


<robot xmlns:xacro="http://www.ros.org/wiki/xacro" name="mp">

    <xacro:include filename="$(find mp_description)/urdf/mp_gazebo.xacro"/>
    <xacro:include filename="$(find mp_description)/urdf/mp_ros2_control.xacro"/>

    <xacro:property name="PI" value="3.14159265359" />
    <xacro:property name="effort" value="30.0" />
    <xacro:property name="velocity" value="10.0" />

    <xacro:macro name="default_inertial" params="mass">
        <inertial>
            <mass value="${mass}"/>
            <inertia ixx="1.0" ixy="0.0" ixz="0.0"
                     iyy="1.0" iyz="0.0"
                     izz="1.0"/>
        </inertial>
    </xacro:macro>

    <xacro:macro name="default_transmission" params="number">
        <transmission name="transmission_${number}">
            <plugin>transmission_interface/SimpleTransmission</plugin>
            <actuator name="motor_${number}" role="actuator1"/>
            <joint name="joint_${number}" role="joint1">
                <mechanical_reduction>1.0</mechanical_reduction>
            </joint>
        </transmission>
    </xacro:macro>

    <link name="world"/>

    <link name="rack">
        <xacro:default_inertial mass="2.0"/>  
        <visual>
            <origin rpy="${PI/2} 0 ${PI/2}" xyz="-2 2 0"/>
            <geometry>
                <mesh filename="package://mp_description/meshes/mp_rack.STL" scale="0.01 0.01 0.01"/>
            </geometry>
        </visual>
        <collision>
            <origin rpy="${PI/2} 0 ${PI/2}" xyz="-2 2 0"/>
            <geometry>
                <mesh filename="package://mp_description/meshes/mp_rack.STL" scale="0.01 0.01 0.01"/>
            </geometry>
        </collision>
    </link>

    <joint name="rack_joint" type="fixed">
        <parent link="world"/>
        <child link="rack"/>
        <origin rpy="0 0 0" xyz="0 0 0"/> 
    </joint>

    <link name="pallet">
        <xacro:default_inertial mass="2.0"/>  
        <visual>
            <origin rpy="${PI/2} 0 ${PI/2}" xyz="1 1.5 0"/>
            <geometry>
                <mesh filename="package://mp_description/meshes/mp_pallet.STL" scale="0.01 0.01 0.01"/>
            </geometry>
        </visual>
        <collision>
            <origin rpy="${PI/2} 0 ${PI/2}" xyz="1 1.5 0"/>
            <geometry>
                <mesh filename="package://mp_description/meshes/mp_pallet.STL" scale="0.01 0.01 0.01"/>
            </geometry>
        </collision>
    </link>

    <joint name="pallet_joint" type="fixed">
        <parent link="world"/>
        <child link="pallet"/>
        <origin rpy="0 0 0" xyz="0 0 0"/> 
    </joint>

    <link name="cube">
        <xacro:default_inertial mass="2.0"/>  
        <visual>
            <origin rpy="${PI/2} 0 ${PI/2}" xyz="2 2 0.1"/>
            <geometry>
                <mesh filename="package://mp_description/meshes/mp_cube.STL" scale="0.01 0.01 0.01"/>
            </geometry>
        </visual>
        <collision>
            <origin rpy="${PI/2} 0 ${PI/2}" xyz="2 2 0.1"/>
            <geometry>
                <mesh filename="package://mp_description/meshes/mp_cube.STL" scale="0.01 0.01 0.01"/>
            </geometry>
        </collision>
    </link>

    <joint name="cube_joint" type="fixed">
        <parent link="world"/>
        <child link="cube"/>
        <origin rpy="0 0 0" xyz="0 0 0"/> 
    </joint>

    <link name="base_link">
        <xacro:default_inertial mass="1.0"/>
        <visual>
            <origin rpy="${PI/2} 0 0" xyz="-0.6 0.6 0"/>
            <geometry>
                <mesh filename="package://mp_description/meshes/mp_base.STL" scale="0.01 0.01 0.01"/>
            </geometry>
        </visual>
        <collision>
            <origin rpy="${PI/2} 0 0" xyz="-0.6 0.6 0"/>
            <geometry>
                <mesh filename="package://mp_description/meshes/mp_base.STL" scale="0.01 0.01 0.01"/>
            </geometry>
        </collision>
    </link>

    <joint name="virtual_joint" type="fixed">
        <parent link="world"/>
        <child link="base_link"/>
        <origin rpy="0 0 0" xyz="0 0 0"/>
    </joint>

    <link name="mp_link1">
        <xacro:default_inertial mass="0.1"/>
        <visual>
            <origin rpy="${PI/2} 0 0" xyz="-0.4 0.4 0"/>
            <geometry>
                <mesh filename="package://mp_description/meshes/mp_link1.STL" scale= "0.01 0.01 0.01"/>
            </geometry>
        </visual>
        <collision>
            <origin rpy="${PI} ${PI/2} ${PI}" xyz="-0.4 0.4 0"/>
            <geometry>
                <cylinder radius="0.1" length="0.1"/> <!-- Adjust dimensions -->
            </geometry>
        </collision>
    </link>

    <joint name="joint_1" type="revolute">
        <parent link="base_link"/>
        <child link="mp_link1"/>
        <axis xyz="0 0 1"/>
        <origin rpy="0 0 0" xyz="0 0 0.4"/>
        <limit lower="-${PI}" upper="${PI}" effort="${effort}" velocity="${velocity}"/>    </joint>

    <link name="mp_link2">
        <xacro:default_inertial mass="0.1"/>
        <visual>
            <origin rpy="${PI} 0 ${PI}" xyz="0.3 -0.3 1"/>
            <geometry>
                <mesh filename="package://mp_description/meshes/mp_link2.STL" scale= "0.01 0.01 0.01"/>
            </geometry>
        </visual>
        <collision>
            <origin rpy="${PI} ${PI/2} ${PI}" xyz="0.3 -0.3 1"/>
            <geometry>
                <cylinder radius="0.1" length="0.1"/> <!-- Adjust dimensions -->
            </geometry>
        </collision>
    </link>

    <joint name="joint_2" type="revolute">
        <parent link="mp_link1"/>
        <child link="mp_link2"/>
        <axis xyz="0 0 1"/>
        <origin rpy="0 ${PI/2} 0" xyz="0.8 0 0.5"/>
        <limit lower="-${PI/2}" upper="${PI/2}" effort="${effort}" velocity="${velocity}"/>
    </joint>

    <link name="mp_link3">
        <xacro:default_inertial mass="0.1"/>
        <visual>
            <origin rpy="0 -${PI/2} 0" xyz="0.4 -0.25 0.0"/>
            <geometry>
                <mesh filename="package://mp_description/meshes/mp_link3.STL" scale= "0.01 0.01 0.01"/>
            </geometry>
        </visual>
        <collision>
            <origin rpy="${PI} ${PI/2} ${PI}" xyz="0.4 -0.25 0.0"/>
            <geometry>
                <cylinder radius="0.1" length="0.1"/> <!-- Adjust dimensions -->
            </geometry>
        </collision>
    </link>

    <joint name="joint_3" type="revolute">
        <parent link="mp_link2"/>
        <child link="mp_link3"/>
        <axis xyz="0 0 1"/>
        <origin rpy="0 -${PI/2} 0" xyz="-1.6 0 0.55"/>
        <limit lower="-${PI/2}" upper="${PI/2}" effort="${effort}" velocity="${velocity}"/>
    </joint>

    <link name="mp_link4">
        <xacro:default_inertial mass="0.1"/>
        <visual>
            <origin rpy="0 -${PI/2} 0" xyz="0.4 -0.25 -0.65"/>
            <geometry>
                <mesh filename="package://mp_description/meshes/mp_link4.STL" scale= "0.01 0.01 0.01"/>
            </geometry>
        </visual>
        <collision>
            <origin rpy="${PI} ${PI/2} ${PI}" xyz="0.4 -0.25 -0.65"/>
            <geometry>
                <cylinder radius="0.1" length="0.1"/> <!-- Adjust dimensions -->
            </geometry>
        </collision>
    </link>

    <joint name="joint_4" type="revolute">
        <parent link="mp_link3"/>
        <child link="mp_link4"/>
        <axis xyz="0 0 1"/>
        <origin rpy="0 ${PI/2} 0" xyz="-0.9 0 0.4"/>
        <limit lower="-${PI/2}" upper="${PI/2}" effort="${effort}" velocity="${velocity}"/>
    </joint>

    <link name="mp_link5">
        <xacro:default_inertial mass="0.1"/>
        <visual>
            <origin rpy="${PI} ${PI/2} ${PI}" xyz="-0.3 -0.2 0.6"/>
            <geometry>
                <mesh filename="package://mp_description/meshes/mp_link5.STL" scale= "0.01 0.01 0.01"/>
            </geometry>
        </visual>
        <collision>
            <origin rpy="${PI} ${PI/2} ${PI}" xyz="-0.3 -0.2 0.6"/>
            <geometry>
                <cylinder radius="0.1" length="0.1"/> <!-- Adjust dimensions -->
            </geometry>
        </collision>
    </link>

    <joint name="joint_5" type="revolute">
        <parent link="mp_link4"/>
        <child link="mp_link5"/>
        <axis xyz="0 0 1"/>
        <origin rpy="0 ${3*PI/2} 0" xyz="-1.3 0 -0.4"/>
        <limit lower="-${PI/2}" upper="${PI/2}" effort="${effort}" velocity="${velocity}"/>
    </joint>

    <link name="mp_link6">
        <xacro:default_inertial mass="0.1"/>
        <visual>
            <origin rpy="${PI/2} 0 0" xyz="-0.25 0.25 0"/>
            <geometry>
                <mesh filename="package://mp_description/meshes/mp_link6.STL" scale= "0.01 0.01 0.01"/>
            </geometry>
        </visual>
        <collision>
            <origin rpy="${PI} ${PI/2} ${PI}" xyz="-0.25 0.25 0"/>
            <geometry>
                <cylinder radius="0.1" length="0.1"/> <!-- Adjust dimensions -->
            </geometry>
        </collision>
    </link>

    <joint name="joint_6" type="revolute">
        <parent link="mp_link5"/>
        <child link="mp_link6"/>
        <axis xyz="0 0 1"/>
        <origin rpy="0 ${PI/2} 0" xyz="0.6 0 0.4"/>
        <limit lower="-${PI/2}" upper="${PI/2}" effort="${effort}" velocity="${velocity}"/>
    </joint>

    <link name="gripper_support">
        <xacro:default_inertial mass="0.05"/>
        <visual>
            <origin rpy="${PI/2} 0 ${PI/2}" xyz="-0.2 -0.2 0.1"/>
            <geometry>
                <mesh filename="package://mp_description/meshes/mp_gripper.STL" scale= "0.01 0.01 0.01"/>
            </geometry>
        </visual>
        <collision>
            <origin rpy="${PI} ${PI/2} ${PI}" xyz="-0.2 -0.2 0.1"/>
            <geometry>
                <cylinder radius="0.1" length="0.1"/> <!-- Adjust dimensions -->
            </geometry>
        </collision>
    </link>

    <joint name="joint_7" type="fixed">
        <parent link="mp_link6"/>
        <child link="gripper_support"/>
        <origin rpy="0 0 0" xyz="0 0 0"/>
    </joint>


    <link name="gripper_right">
        <xacro:default_inertial mass="0.01"/>
        <visual>
            <origin rpy="${PI/2} 0 ${3*PI/2}" xyz="0.41 0.95 0"/>
            <geometry>
                <mesh filename="package://mp_description/meshes/mp_gripperlink2.STL" scale="0.01 0.01 0.01"/>
            </geometry>
        </visual>
        <collision>
            <origin rpy="${PI/2} 0 ${3*PI/2}" xyz="0.41 0.95 0"/>
            <geometry>
                <box size="0.01 0.01 0.01"/>
            </geometry>
        </collision>
    </link>

    <joint name="joint_8" type="revolute">
        <parent link="gripper_support"/>
        <child link="gripper_right"/>
        <axis xyz="0 0 1"/>
        <origin rpy="0 -${PI/2} 0" xyz="0 -0.11 0.5"/>
        <limit lower="-${PI/2}" upper="0.0" effort="${effort}" velocity="${velocity}"/>
    </joint>

    <link name="gripper_left">
        <xacro:default_inertial mass="0.01"/>
        <visual>
            <origin rpy="${PI/2} 0 ${3*PI/2}" xyz="0.41 0.1 0"/>
            <geometry>
                <mesh filename="package://mp_description/meshes/mp_gripperlink1.STL" scale="0.01 0.01 0.01"/>
            </geometry>
        </visual>
        <collision>
            <origin rpy="${PI/2} 0 ${3*PI/2}" xyz="0.41 0.1 0"/>
            <geometry>
                <box size="0.01 0.01 0.01"/>
            </geometry>
        </collision>
    </link>

    <joint name="joint_9" type="revolute">
        <parent link="gripper_support"/>
        <child link="gripper_left"/>
        <axis xyz="0 0 1"/>
        <origin rpy="0 -${PI/2} 0" xyz="0 0.11 0.5"/>
        <mimic joint="joint_8" multiplier="-1" offset="0"/> <!-- offset --> 
        <!-- <disable_collisions link1="gripper_left" link2="gripper_right" reason="Never"/> -->
        <limit lower="0.0" upper="${PI/2}" effort="${effort}" velocity="${velocity}"/>
    </joint>

    <!-- <joint name="gripper_right_j_mimic" type="fixed">
        <parent link="world"/>
        <child link="dummy_mimic_fix"/>
    </joint>
    <link name="dummy_mimic_fix"/> -->

    <link name="rgb_camera">
        <xacro:default_inertial mass="0.001"/>
        <visual>
            <origin rpy="${PI/2} ${PI} ${PI/2}" xyz="-0.12 0.1 0.1"/>
            <geometry>
                <mesh filename="package://mp_description/meshes/pi_camera.STL" scale="0.01 0.01 0.01"/>
            </geometry>
        </visual>
        <collision>
            <origin rpy="0 0 0" xyz="0 0 0"/>
            <geometry>
                <mesh filename="package://mp_description/meshes/pi_camera.STL" scale="0.01 0.01 0.01"/>
            </geometry>
        </collision>
    </link>

    <joint name ="rgb_camera_joint" type="fixed">
        <parent link="gripper_support"/>
        <child link = "rgb_camera"/>
        <origin xyz="-0.4 0 0" rpy="0 -${PI/2} 0"/>
        <!-- y - ${PI} -->
    </joint>

    <link name="camera_link_optical"/>

    <joint name="camera_optical_joint" type="fixed">
        <parent link="rgb_camera"/>
        <child link="camera_link_optical"/>
        <origin xyz="0 0 0" rpy="0 ${3*PI/2} ${PI}"/>
        <!-- 0.55 0.125 -->
    </joint>

    <xacro:default_transmission number="1"/>
    <xacro:default_transmission number="2"/>
    <xacro:default_transmission number="3"/>
    <xacro:default_transmission number="4"/>
    <xacro:default_transmission number="5"/>
    <xacro:default_transmission number="6"/>
    <xacro:default_transmission number="7"/>
    <xacro:default_transmission number="8"/>

</robot>